Workbook

Sheet Notes
A1: Analysis Conducted: April 2026.
A3: Data Source Information
A5: • Primary Source: Apple Inc. Annual Reports (Form 10-K) for fiscal years 2021 to 2025.
A6: • Extraction Point: Data sourced from the Condensed Consolidated Statements of Operations
A7: (Income Statement) and the Products and Services Performance tables.
A8: • Access Method: SEC EDGAR Database (sec.gov).
A10: Key Definitions and Methodology
A12: • Currency: All figures are reported in Millions of USD ($).
A13: • Fiscal Year: Apple's fiscal year ends on the last Saturday of September (e.g, FY2025 ended Sept 27, 2025.
A14: • Segment Definitions: Products (Includes iPhone, Mac, iPad, and Wearables/Home/Accessories)
A15: Services (Includes App Store, Apple Music, iCloud, Apple Pay, and Apple TV+).
A16: • Gross Margin (%) Calculation: Calculated as Gross Profit divided by Total Revenue.
... A34: • Segment margin assumptions held constant across forecast period. Mix effect is isolated as the primary margin driver.

Sheet Insights
B2: Financial Performance Analysis-Apple Inc.
B4: Executive Summary
B6: Apple's revenue mix shifted materially toward high-margin Services between FY2021-FY2025. While Products revenue plateaued after FY2022, Services sustained consolidated
B7: growth and expanded blended gross margins from 41.78% to 46.91%. Scenario forecasting suggests future margin expansion remains primarily dependent on continued Services
B8: monetization and installed base growth.
B10: Section 1: Revenue Growth
B12: • Services Revenue grew at 12.39% 4-year CAGR (FY2021-2025), consistently outpacing total revenue growth of 3.28%, confirming Services as the primary growth
B13: engine.
B14: • Products Revenue peaked at $316,199M in FY2022 before declining to $307,003M by FY2025 - a peak and decline pattern, not mere stagnation, signalling market
B15: saturation in core hardware segments.
B16: • Total Revenue growth ranged from -2.80% to 7.79% annually, highlighting Apple's dependence on Services to offset hardware cyclicality. | N16: rce
B18: Section 2: Products Trends
B20: • Products Revenue declined from its FY2022 peak of $316,199M to $307,003M in FY2025 - a 2.9% contraction over three years.
B21: • Bear Case projects further decline to $300,894M by 2027, reflecting China demand risk and absence of major upgrade cycles.
B22: • Bull Case projects modest recovery to $325,699M by FY2027, contingent on new product category launches and ASP expansion.
B24: Section 3: Revenue Mix Shift
B26: • Services contribution to total revenue expanded from 18.70% in FY2021 to 26.23% in FY2025 - a 756 basis point structural shift.
B27: • Base Case projects Services mix reaching 30.65% by FY2027, crossing the 30% threshold for the first time in Apple's history.
B28: • This shift reduces Apple's reliance on one-time hardware purchase cycles in favour of high-retention recurring revenue.
B30: Section 4: Margin Implications
B32: • Services gross margin of 75.41% versus Products gross margin of 36.77% creates a 38.64 percentage point spread - every percentage point of Services mix shift
B33: adds approximately 39 basis points to blended gross margin.
B34: • Blended gross margin expanded from 41.78% in FY2021 to 46.91% in FY2025, directly tracking the Services mix increase.
... B53: • Scenarios reflect regulatory risk (EU App Store), China demand exposure, and installed base monetization opportunity respectively.

Sheet Apple_SEC_Data
A1: All figures are in USD Millions
A3: Table 1: | B3: Revenue
A5: Year | B5: Services | C5: Products | D5: Total Revenue | E5: Services (Revenue Contribution) % | F5: Products (Revenue Contribution) % | G5: Services Revenue Growth % | H5: Products Revenue Growth % | I5: Total Revenue Growth %
A6: 2021 | B6: 68425 | C6: 297392 | D6: =B6+C6 -> 365817 | E6: =B6/D6 -> 0.18704708 | F6: =C6/D6 -> 0.81295292
A7: 2022 | B7: 78129 | C7: 316199 | D7: =B7+C7 -> 394328 | E7: =B7/D7 -> 0.19813201 | F7: =C7/D7 -> 0.80186799 | G7: =(B7-B6)/B6 -> 0.14181951 | H7: =(C7-C6)/C6 -> 0.063239764 | I7: =(D7-D6)/D6 -> 0.077937876
A8: 2023 | B8: 85200 | C8: 298085 | D8: =B8+C8 -> 383285 | E8: =B8/D8 -> 0.2222889 | F8: =C8/D8 -> 0.7777111 | G8: =(B8-B7)/B7 -> 0.090504166 | H8: =(C8-C7)/C7 -> -0.057286709 | I8: =(D8-D7)/D7 -> -0.028004605
A9: 2024 | B9: 96169 | C9: 294866 | D9: =B9+C9 -> 391035 | E9: =B9/D9 -> 0.24593451 | F9: =C9/D9 -> 0.75406549 | G9: =(B9-B8)/B8 -> 0.12874413 | H9: =(C9-C8)/C8 -> -0.010798933 | I9: =(D9-D8)/D8 -> 0.020219941
A10: 2025 | B10: 109158 | C10: 307003 | D10: =B10+C10 -> 416161 | E10: =B10/D10 -> 0.26229752 | F10: =C10/D10 -> 0.73770248 | G10: =(B10-B9)/B9 -> 0.13506431 | H10: =(C10-C9)/C9 -> 0.04116107 | I10: =(D10-D9)/D9 -> 0.064255118
A13: Table 2: | B13: Margin
A15: Year | B15: Services Gross Profit | C15: Products Gross Profit | D15: Total Gross Profit | E15: Net Income | F15: Services Gross Margin % | G15: Products Gross Margin % | H15: Total Gross Margin % | I15: Net Margin %
A16: 2021 | B16: 47710 | C16: 105126 | D16: =B16+C16 -> 152836 | E16: 94680 | F16: =B16/B6 -> 0.69725977 | G16: =C16/C6 -> 0.35349303 | H16: =D16/D6 -> 0.4177936 | I16: =E16/D6 -> 0.25881793
A17: 2022 | B17: 56054 | C17: 114728 | D17: =B17+C17 -> 170782 | E17: 99803 | F17: =B17/B7 -> 0.71745447 | G17: =C17/C7 -> 0.3628348 | H17: =D17/D7 -> 0.43309631 | I17: =E17/D7 -> 0.25309641
A18: 2023 | B18: 60345 | C18: 108803 | D18: =B18+C18 -> 169148 | E18: 96995 | F18: =B18/B8 -> 0.70827465 | G18: =C18/C8 -> 0.36500663 | H18: =D18/D8 -> 0.4413113 | I18: =E18/D8 -> 0.25306234
A19: 2024 | B19: 71050 | C19: 109633 | D19: =B19+C19 -> 180683 | E19: 93736 | F19: =B19/B9 -> 0.73880356 | G19: =C19/C9 -> 0.37180618 | H19: =D19/D9 -> 0.4620635 | I19: =E19/D9 -> 0.23971256
A20: 2025 | B20: 82314 | C20: 112887 | D20: =B20+C20 -> 195201 | E20: 112010 | F20: =B20/B10 -> 0.75408124 | G20: =C20/C10 -> 0.3677065 | H20: =D20/D10 -> 0.46905164 | I20: =E20/D10 -> 0.26915064

Sheet Forecast
A1: Scenario Model - Apple Inc. (2026-2027)
A3: CAGR Calculation | C3: Formula | E3: Source
A5: Services CAGR | C5: =(Apple_SEC_Data!B10/Apple_SEC_Data!B6)^(1/4)-1 -> 0.12385476 | E5: Apple 10-K FY2021 & 2025, SEC EDGAR - 4 year CAGR
A6: Products CAGR | C6: =(Apple_SEC_Data!C10/Apple_SEC_Data!C6)^(1/4)-1 -> 0.0079832943 | E6: Apple 10-K FY2021 & 2025, SEC EDGAR - 4 year CAGR
A7: Services Gross Margin % | C7: =Apple_SEC_Data!B20/Apple_SEC_Data!B10 -> 0.75408124 | E7: Apple 10-K FY2025, Income Statement (Services GP/Revenue)
A8: Products Gross Margin % | C8: =Apple_SEC_Data!C20/Apple_SEC_Data!C10 -> 0.3677065 | E8: Apple 10-K FY2025, Income Statement (Products GP/Revenue)
A9: R&D % of Revenue | C9: =34550/Apple_SEC_Data!D10 -> 0.083020754 | E9: Apple 10-K FY2025, TABLE9 (hardcoded - not in clean_data)
A10: SG&A % of Revenue | C10: =27601/Apple_SEC_Data!D10 -> 0.066322889 | E10: Apple 10-K FY2025, TABLE9 (hardcoded - not in clean_data)
A11: Effective Tax Rate | C11: 0.1561 | E11: Apple 10-K FY2025, Tax Provision/Pre-Tax Income (20,719/132,729)
A13: Active Scenario: | B13: Base
A15: ASSUMPTION INPUTS | B15: Bear | C15: Base | D15: Bull | E15: Active | G15: Rationale
A17: Services Revenue Growth | B17: 0.08 | C17: =C5 -> 0.12385476 | D17: 0.15 | E17: =IF($B$13="Bear",B17,IF($B$13="Bull",D17,C17)) -> 0.12385476 | G17: Historical 4-year CAGR from SEC filings. Bear = EU App Store regulatory risk. Bull = expanding installed base monetization.
A18: Products Revenue Growth | B18: -0.01 | C18: =C6 -> 0.0079832943 | D18: 0.03 | E18: =IF($B$13="Bear",B18,IF($B$13="Bull",D18,C18)) -> 0.0079832943 | G18: Products peaked $316 B in 2022, declined to $307 B by 2025. Bear = China demand risk. Bull = new product categories.
A19: Services Gross Margin % | B19: 0.74 | C19: =C7 -> 0.75408124 | D19: 0.78 | E19: =IF($B$13="Bear",B19,IF($B$13="Bull",D19,C19)) -> 0.75408124 | G19: Derived from FY2025 10-K. Bear = pricing pressure. Bull = software mix improvement.
A20: Products Gross Margin % | B20: 0.36 | C20: =C8 -> 0.3677065 | D20: 0.39 | E20: =IF($B$13="Bear",B20,IF($B$13="Bull",D20,C20)) -> 0.3677065 | G20: Derived from FY2025 10-K. Bear = input cost inflation. Bull = supply chain optimization.
A21: R&D as % of Revenue | B21: 0.082 | C21: =C9 -> 0.083020754 | D21: 0.075 | E21: =IF($B$13="Bear",B21,IF($B$13="Bull",D21,C21)) -> 0.083020754 | G21: FY2025 actual per TABLE9. Bear = increased AI investment. Bull = efficiency gains.
A22: SG&A as % of Revenue | B22: 0.072 | C22: =C10 -> 0.066322889 | D22: 0.065 | E22: =IF($B$13="Bear",B22,IF($B$13="Bull",D22,C22)) -> 0.066322889 | G22: FY2025 actual per TABLE9. Bear = higher marketing spend. Bull = operating leverage.
A23: Effective Tax Rate | B23: 0.16 | C23: =C11 -> 0.1561 | D23: 0.15 | E23: =IF($B$13="Bear",B23,IF($B$13="Bull",D23,C23)) -> 0.1561 | G23: FY2025 derived rate. Bear = unfavourable jurisdiction mix. Bull = tax optimizaton.
A26: SECTION 2 - Revenue Forecast (USD Millions)
A28: Year | B28: 2025 | C28: 2026 | D28: 2027
A29: Services Revenue | B29: =Apple_SEC_Data!B10 -> 109158 | C29: =B29*(1+E17) -> 122677.74 | D29: =C29*(1+E17) -> 137871.96
A30: Products Revenue | B30: =Apple_SEC_Data!C10 -> 307003 | C30: =B30*(1+E18) -> 309453.9 | D30: =C30*(1+E18) -> 311924.36
A31: Total Revenue | B31: =SUM(B29,B30) -> 416161 | C31: =SUM(C29,C30) -> 432131.63 | D31: =SUM(D29,D30) -> 449796.32
A33: Services Mix % | B33: =B29/B31 -> 0.26229752 | C33: =C29/C31 -> 0.28388974 | D33: =D29/D31 -> 0.30652087
A34: Products Mix % | B34: =B30/B31 -> 0.73770248 | C34: =C30/C31 -> 0.71611026 | D34: =D30/D31 -> 0.69347913
A36: SECTION 3 - Gross Profit Bridge (USD Millions
A38: Year | B38: 2025 | C38: 2026 | D38: 2027
A39: Services Gross Profit | B39: =Apple_SEC_Data!B20 -> 82314 | C39: =C29*E19 -> 92508.981 | D39: =D29*E19 -> 103966.66
A40: Products Gross Profit | B40: =Apple_SEC_Data!C20 -> 112887 | C40: =C30*E20 -> 113788.21 | D40: =D30*E20 -> 114696.61
A41: Total Gross Profit | B41: =SUM(B39,B40) -> 195201 | C41: =SUM(C39,C40) -> 206297.19 | D41: =SUM(D39,D40) -> 218663.27
A43: Services Gross Margin % | B43: =B39/B29 -> 0.75408124 | C43: =C39/C29 -> 0.75408124 | D43: =D39/D29 -> 0.75408124
A44: Products Gross Margin % | B44: =B40/B30 -> 0.3677065 | C44: =C40/C30 -> 0.3677065 | D44: =D40/D30 -> 0.3677065
A45: Blended Gross Margin % | B45: =B41/B31 -> 0.46905164 | C45: =C41/C31 -> 0.47739433 | D45: =D41/D31 -> 0.48613843
A47: SECTION 4 - Income Statement Bridge (USD Millions)
A49: Year | B49: 2025 | C49: 2026 | D49: 2027
A50: Total Revenue | B50: =B31 -> 416161 | C50: =C31 -> 432131.63 | D50: =D31 -> 449796.32
A51: Total Gross Profit | B51: =B41 -> 195201 | C51: =C41 -> 206297.19 | D51: =D41 -> 218663.27
A52: Less: R&D | B52: 34550 | C52: =C50*E21 -> 35875.894 | D52: =D50*E21 -> 37342.429
A53: Less: SG&A | B53: 27601 | C53: =C50*E22 -> 28660.219 | D53: =D50*E22 -> 29831.791
A54: Total Opex | B54: =SUM(B52,B53) -> 62151 | C54: =SUM(C52,C53) -> 64536.113 | D54: =SUM(D52,D53) -> 67174.221
...

Sheet Tableau_Dashboard
A1: Year | B1: Scenario | C1: Services Revenue | D1: Products Revenue | E1: Total Revenue | F1: Services Mix % | G1: Products Mix % | H1: Services Gross Profit | I1: Products Gross Profit | J1: Total Gross Profit | K1: Blended Gross Margin | L1: Net Income | M1: Net Margin
A2: 2021 | B2: Actual | C2: =Apple_SEC_Data!B6 -> 68425 | D2: =Apple_SEC_Data!C6 -> 297392 | E2: =Apple_SEC_Data!D6 -> 365817 | F2: =C2/E2 -> 0.18704708 | G2: =D2/E2 -> 0.81295292 | H2: =Apple_SEC_Data!B16 -> 47710 | I2: =Apple_SEC_Data!C16 -> 105126 | J2: =Apple_SEC_Data!D16 -> 152836 | K2: =J2/E2 -> 0.4177936 | L2: =Apple_SEC_Data!E16 -> 94680 | M2: =L2/E2 -> 0.25881793
A3: 2022 | B3: Actual | C3: =Apple_SEC_Data!B7 -> 78129 | D3: =Apple_SEC_Data!C7 -> 316199 | E3: =Apple_SEC_Data!D7 -> 394328 | F3: =C3/E3 -> 0.19813201 | G3: =D3/E3 -> 0.80186799 | H3: =Apple_SEC_Data!B17 -> 56054 | I3: =Apple_SEC_Data!C17 -> 114728 | J3: =Apple_SEC_Data!D17 -> 170782 | K3: =J3/E3 -> 0.43309631 | L3: =Apple_SEC_Data!E17 -> 99803 | M3: =L3/E3 -> 0.25309641
A4: 2023 | B4: Actual | C4: =Apple_SEC_Data!B8 -> 85200 | D4: =Apple_SEC_Data!C8 -> 298085 | E4: =Apple_SEC_Data!D8 -> 383285 | F4: =C4/E4 -> 0.2222889 | G4: =D4/E4 -> 0.7777111 | H4: =Apple_SEC_Data!B18 -> 60345 | I4: =Apple_SEC_Data!C18 -> 108803 | J4: =Apple_SEC_Data!D18 -> 169148 | K4: =J4/E4 -> 0.4413113 | L4: =Apple_SEC_Data!E18 -> 96995 | M4: =L4/E4 -> 0.25306234
A5: 2024 | B5: Actual | C5: =Apple_SEC_Data!B9 -> 96169 | D5: =Apple_SEC_Data!C9 -> 294866 | E5: =Apple_SEC_Data!D9 -> 391035 | F5: =C5/E5 -> 0.24593451 | G5: =D5/E5 -> 0.75406549 | H5: =Apple_SEC_Data!B19 -> 71050 | I5: =Apple_SEC_Data!C19 -> 109633 | J5: =Apple_SEC_Data!D19 -> 180683 | K5: =J5/E5 -> 0.4620635 | L5: =Apple_SEC_Data!E19 -> 93736 | M5: =L5/E5 -> 0.23971256
A6: 2025 | B6: Actual | C6: =Apple_SEC_Data!B10 -> 109158 | D6: =Apple_SEC_Data!C10 -> 307003 | E6: =Apple_SEC_Data!D10 -> 416161 | F6: =C6/E6 -> 0.26229752 | G6: =D6/E6 -> 0.73770248 | H6: =Apple_SEC_Data!B20 -> 82314 | I6: =Apple_SEC_Data!C20 -> 112887 | J6: =Apple_SEC_Data!D20 -> 195201 | K6: =J6/E6 -> 0.46905164 | L6: =Apple_SEC_Data!E20 -> 112010 | M6: =L6/E6 -> 0.26915064
A7: 2026 | B7: Bear | C7: 117891 | D7: 303933 | E7: =SUM(C7,D7) -> 421824 | F7: =C7/E7 -> 0.27947912 | G7: =D7/E7 -> 0.72052088 | H7: =C7*0.74 -> 87239.34 | I7: =D7*0.36 -> 109415.88 | J7: =SUM(H7,I7) -> 196655.22 | K7: =J7/E7 -> 0.46620207 | L7: 110353 | M7: =L7/E7 -> 0.26160911
A8: 2026 | B8: Base | C8: 122678 | D8: 309454 | E8: =SUM(C8,D8) -> 432132 | F8: =C8/E8 -> 0.28389011 | G8: =D8/E8 -> 0.71610989 | H8: 92509 | I8: 113788 | J8: =SUM(H8,I8) -> 206297 | K8: =J8/E8 -> 0.47739348 | L8: 119361 | M8: =L8/E8 -> 0.27621421
A9: 2026 | B9: Bull | C9: 125532 | D9: 316213 | E9: =SUM(C9,D9) -> 441745 | F9: =C9/E9 -> 0.284173 | G9: =D9/E9 -> 0.715827 | H9: 97915 | I9: 123323 | J9: =SUM(H9,I9) -> 221238 | K9: =J9/E9 -> 0.5008274 | L9: 135212 | M9: =L9/E9 -> 0.30608609
A10: 2027 | B10: Bear | C10: 127322 | D10: 300894 | E10: =SUM(C10,D10) -> 428216 | F10: =C10/E10 -> 0.29733125 | G10: =D10/E10 -> 0.70266875 | H10: 94218 | I10: 108322 | J10: =SUM(H10,I10) -> 202540 | K10: =J10/E10 -> 0.4729856 | L10: 114470 | M10: =L10/E10 -> 0.26731836
A11: 2027 | B11: Base | C11: 137872 | D11: 311924 | E11: =SUM(C11,D11) -> 449796 | F11: =C11/E11 -> 0.30652118 | G11: =D11/E11 -> 0.69347882 | H11: 103967 | I11: 114697 | J11: =SUM(H11,I11) -> 218664 | K11: =J11/E11 -> 0.48614038 | L11: 127571 | M11: =L11/E11 -> 0.28361969
A12: 2027 | B12: Bull | C12: 144361 | D12: 325699 | E12: =SUM(C12,D12) -> 470060 | F12: =C12/E12 -> 0.30711186 | G12: =D12/E12 -> 0.69288814 | H12: 112602 | I12: 127023 | J12: =SUM(H12,I12) -> 239625 | K12: =J12/E12 -> 0.50977535 | L12: 147471 | M12: =L12/E12 -> 0.31372803

Sheet Attribution
A1: Scenario | B1: Driver | C1: Basis Points
A2: Bear | B2: Mix Effect | C2: 133
A3: Bear | B3: Segment Effect | C3: -94
A4: Base | B4: Mix Effect | C4: 171
A5: Base | B5: Segment Effect | C5: 0
A6: Bull | B6: Mix Effect | C6: 175
A7: Bull | B7: Segment Effect | C7: 232
